{
  "cve": {
    "data_type": "CVE",
    "data_format": "MITRE",
    "data_version": "4.0",
    "CVE_data_meta": {
      "ID": "CVE-2008-4099"
    },
    "affects": {
      "vendor": {
        "vendor_data": [
          {
            "vendor_name": "debian",
            "product": {
              "product_data": [
                {
                  "product_name": "python-dns",
                  "version": {
                    "version_data": [
                      {
                        "version_value": "2.3.0-1"
                      },
                      {
                        "version_value": "2.3.0-2"
                      },
                      {
                        "version_value": "2.3.0-3"
                      },
                      {
                        "version_value": "2.3.0-4"
                      },
                      {
                        "version_value": "2.3.0-5"
                      },
                      {
                        "version_value": "2.3.0-5.1"
                      },
                      {
                        "version_value": "2.3.0-6"
                      },
                      {
                        "version_value": "2.3.1-1"
                      },
                      {
                        "version_value": "2.3.1-2"
                      },
                      {
                        "version_value": "2.3.1-3"
                      }
                    ]
                  }
                }
              ]
            }
          }
        ]
      }
    },
    "problemtype": {
      "problemtype_data": [
        {
          "description": [
            {
              "lang": "en",
              "value": "CWE-16"
            }
          ]
        }
      ]
    },
    "references": {
      "reference_data": [
        {
          "url": "http://bugs.debian.org/cgi-bin/bugreport.cgi?bug=490217"
        },
        {
          "url": "http://packages.debian.org/changelogs/pool/main/p/python-dns/python-dns_2.3.3-1/changelog"
        },
        {
          "url": "http://www.openwall.com/lists/oss-security/2008/09/11/1"
        },
        {
          "url": "http://www.openwall.com/lists/oss-security/2008/09/16/4"
        }
      ]
    },
    "description": {
      "description_data": [
        {
          "lang": "en",
          "value": "PyDNS (aka python-dns) before 2.3.1-4 in Debian GNU/Linux does not use random source ports or transaction IDs for DNS requests, which makes it easier for remote attackers to spoof DNS responses, a different vulnerability than CVE-2008-1447."
        }
      ]
    }
  },
  "configurations": {
    "CVE_data_version": "4.0",
    "nodes": [
      {
        "operator": "AND",
        "children": [
          {
            "operator": "OR",
            "cpe": [
              {
                "vulnerable": true,
                "cpeMatchString": "cpe:/a:debian:python-dns:2.3.0-1",
                "cpe23Uri": "cpe:2.3:a:debian:python-dns:2.3.0-1:*:*:*:*:*:*:*"
              },
              {
                "vulnerable": true,
                "cpeMatchString": "cpe:/a:debian:python-dns:2.3.0-2",
                "cpe23Uri": "cpe:2.3:a:debian:python-dns:2.3.0-2:*:*:*:*:*:*:*"
              },
              {
                "vulnerable": true,
                "cpeMatchString": "cpe:/a:debian:python-dns:2.3.0-3",
                "cpe23Uri": "cpe:2.3:a:debian:python-dns:2.3.0-3:*:*:*:*:*:*:*"
              },
              {
                "vulnerable": true,
                "cpeMatchString": "cpe:/a:debian:python-dns:2.3.0-4",
                "cpe23Uri": "cpe:2.3:a:debian:python-dns:2.3.0-4:*:*:*:*:*:*:*"
              },
              {
                "vulnerable": true,
                "cpeMatchString": "cpe:/a:debian:python-dns:2.3.0-5",
                "cpe23Uri": "cpe:2.3:a:debian:python-dns:2.3.0-5:*:*:*:*:*:*:*"
              },
              {
                "vulnerable": true,
                "cpeMatchString": "cpe:/a:debian:python-dns:2.3.0-5.1",
                "cpe23Uri": "cpe:2.3:a:debian:python-dns:2.3.0-5.1:*:*:*:*:*:*:*"
              },
              {
                "vulnerable": true,
                "cpeMatchString": "cpe:/a:debian:python-dns:2.3.0-6",
                "cpe23Uri": "cpe:2.3:a:debian:python-dns:2.3.0-6:*:*:*:*:*:*:*"
              },
              {
                "vulnerable": true,
                "cpeMatchString": "cpe:/a:debian:python-dns:2.3.1-1",
                "cpe23Uri": "cpe:2.3:a:debian:python-dns:2.3.1-1:*:*:*:*:*:*:*"
              },
              {
                "vulnerable": true,
                "cpeMatchString": "cpe:/a:debian:python-dns:2.3.1-2",
                "cpe23Uri": "cpe:2.3:a:debian:python-dns:2.3.1-2:*:*:*:*:*:*:*"
              },
              {
                "vulnerable": true,
                "cpeMatchString": "cpe:/a:debian:python-dns",
                "cpe23Uri": "cpe:2.3:a:debian:python-dns:*:*:*:*:*:*:*:*",
                "versionEndIncluding": "2.3.1-3"
              }
            ]
          },
          {
            "operator": "OR",
            "cpe": [
              {
                "vulnerable": false,
                "cpeMatchString": "cpe:/a:debian:linux:unknown:unknown:etch",
                "cpe23Uri": "cpe:2.3:a:debian:linux:unknown:unknown:etch:*:*:*:*:*"
              }
            ]
          }
        ]
      }
    ]
  },
  "impact": {
    "baseMetricV2": {
      "cvssV2": {
        "vectorString": "(AV:N/AC:L/Au:N/C:N/I:P/A:P)",
        "accessVector": "NETWORK",
        "accessComplexity": "LOW",
        "authentication": "NONE",
        "confidentialityImpact": "NONE",
        "integrityImpact": "PARTIAL",
        "availabilityImpact": "PARTIAL",
        "baseScore": 6.4
      },
      "severity": "MEDIUM",
      "exploitabilityScore": 10.0,
      "impactScore": 4.9,
      "obtainAllPrivilege": false,
      "obtainUserPrivilege": false,
      "obtainOtherPrivilege": false,
      "userInteractionRequired": false
    }
  },
  "publishedDate": "2008-09-18T17:59Z",
  "lastModifiedDate": "2008-09-19T04:00Z"
}